<!-- Author: OpenAI
Modified by: Julio Cesar RAMIREZ
Institution: ESTIA

Modified in November 2023 by J.Edgar Hernandez Cancino EStrada
B.S. in Robotics and Digital Systems Engineering (June, 2024)
Tecnologico de Monterrey -->
<mujoco>

    <body name="robot0:gripper_base_link" pos="0 0 -0.157">
        <geom material="greend" name="robot0:gripper_base_link" mesh="robot0:gripperSF_base_link" quat="0 0 0 1"/>

        <!-- left finger -->
        <!-- <body name="robot0:left_finger" pos="0.025 -0.03 0.15" quat="0 0 0 1"> -->
        <body name="robot0:left_finger" pos="0.025 -0.032 0.09" quat="0 0 0.382683432 0.92386953">
            <geom material="orangel" name="robot0:left_finger" mesh="robot0:SFleft_finger"/>
            <joint name="robot0:left_finger_joint" axis="0 -1 0" type="slide"
                range="-0.03 0.006" pos="0 0 0"/>
        </body>

        <!-- right finger -->
        <body name="robot0:right_finger" pos="-0.025 0.032 0.09" quat="-.92386953 -.382683432 0 0">
        <!-- <body name="robot0:right_finger" pos="0.025 0.03 0.15" quat="0 0 0 1"> -->
            <geom material="orangel" name="robot0:right_finger" mesh="robot0:SFleft_finger"/>
            <joint name="robot0:right_finger_joint" axis="0 1 0" type="slide"
                range="-0.03 0.006" pos="0 0 0"/>
        </body>
    </body>
    
    
</mujoco>